Workbook

Sheet Resumen
A1: CONTROL OPERATIVO ORVANN | D1: Recordatorios | F1: Pendientes
A2: Última actualización | B2: 46067 | D2: Cuenta BC (empresarial o la de Julieta) - Celular y whatsapp para historias (Grupo de difusión) | F2: ITEM | G2: Valor | H2: NOTAS
D3: Mercado Pago y que más necesitamos para funcionar como pyme | F3: Tubo perchero | G3: 150000
A4: RESUMEN FINANCIERO | D4: Agregar proyección al por mayor y packs (Como se vende asi y como conversa con gran diferencia de precio) | F4: Ganchos | G4: 80000
A5: Inventario a costo: | B5: =Inventario!F2 -> 9858000 | D5: Proyección más clara de punto de equilibrio | F5: Espejo cuerpo completo | G5: 250000
A6: Inventario a precio venta: | B6: =Inventario!G2 -> 19460000 | D6: Como funciona shopify | F6: Estantería | H6: Viene en obra ?
A7: Ventas del mes: | B7: =SUMIF(Ventas!A:A,">="&DATE(YEAR(TODAY()),MONTH(TODAY()),1),Ventas!E:E) -> 320000 | D7: Automatizaciones de: Atención al cliente, pedidos, inventario, contabilidad y logística (Cómo la vamos a hacer) | F7: Sillas | G7: 50000
A8: Gastos del mes: | B8: =SUMIF(Gastos!A:A,">="&DATE(YEAR(TODAY()),MONTH(TODAY()),1),Gastos!C:C) -> 4791800 | D8: Enviar instagram a gente y compartir | F8: Luces LED | G8: 0
A9: Cuentas por pagar: | B9: =SUMIF('Pedidos Proveedores'!G:G,"Pendiente",'Pedidos Proveedores'!F:F) -> 9618000 | D9: Que es pixel y como se usa el inventario digital de meta (Inst y Facebook) | F9: Lamparas ? | G9: 0
A10: Utilidad bruta mes: | B10: =B7-SUMIF(Ventas!A:A,">="&DATE(YEAR(TODAY()),MONTH(TODAY()),1),Ventas!D:D)-B8 -> -4631800 | D10: Tema de tener solo uan persona trabajando (Inseguridad) | F10: Cámara seguridad | G10: 250000
D11: Quiero tener algo más dinámico de modelo financiero | F11: Alarma | G11: 120000
D12: Cerrar cuentas pendientes | F12: Candados | G12: 30000
A13: ALERTAS | F13: Registradora | G13: 120000
A14: Productos con stock bajo (<3): | B14: =COUNTIF(Inventario!G:G,"<3")-1 -> 79 | F14: Datafono | G14: 120000
A15: Pedidos pendientes de pago: | B15: =COUNTIF('Pedidos Proveedores'!G:G,"Pendiente") -> 10 | F15: Celular | G15: 300000
F16: Bafle / Parlante | G16: 350000
F17: Router | G17: 40000
A18: INDICADORES CLAVE DE DESEMPEÑO | F18: Ventilador | G18: 100000
D19: Otras referencias (Conocidas pero de nicho) | F19: Kit aseo | G19: 60000
A20: Ticket promedio: | B20: =IFERROR(SUMIF(Ventas!A:A,">="&DATE(YEAR(TODAY()),MONTH(TODAY()),1),Ventas!E:E)/COUNTIF(Ventas!A:A,">="&DATE(YEAR(TODAY()),MONTH(TODAY()),1)),0) -> 160000 | D20: Pulp Fiction (1994) | F20: Tapetes ? | G20: 100000
A21: Prendas vendidas (mes): | B21: =COUNTIF(Ventas!A:A,">="&DATE(YEAR(TODAY()),MONTH(TODAY()),1)) -> 2 | D21: Pedro navaja | F21: Toldo | G21: 500000
A22: Margen bruto %: | B22: =IFERROR((SUMIF(Ventas!A:A,">="&DATE(YEAR(TODAY()),MONTH(TODAY()),1),Ventas!E:E)-SUMIF(Ventas!A:A,">="&DATE(YEAR(TODAY()),MONTH(TODAY()),1),Ventas!D:D))/SUMIF(Ventas!A:A,">="&DATE(YEAR(TODAY()),MONTH(TODAY()),1),Ventas!E:E),0) -> 0.5 | D22: Léon: The Professional
A23: Rotación inventario: | B23: =IFERROR(COUNTIF(Ventas!A:A,">="&DATE(YEAR(TODAY()),MONTH(TODAY()),1))/Inventario!E2,0) -> 0.010869565 | C23: Mide cuántas veces se vende y se reemplaza el inventario en un período de un mes (al no haber ventas, es cero). | D23: Ciudad de Dios | F23: Basura | G23: 30000
A24: Días de inventario: | B24: =IFERROR(Inventario!E2/(COUNTIF(Ventas!A:A,">="&DATE(YEAR(TODAY()),MONTH(TODAY()),1))/30),0) -> 2760 | C24: Mide cuántos días tomaría vender el inventario actual (al no haber ventas, es cero). | D24: Charles Bukowski (Literatura Cruda) | F24: Letrero exterior | G24: 250000 | H24: Viene en obra ?
D25: Héctor Lavoe. Estilo "Vinyl Cover" | F25: Decoración (Cuadros, etc) | G25: 150000
D26: Gabo y Cien Años de Soledad | F26: Plantas | G26: 50000
A27: PUNTO DE EQUILIBRIO | D27: Blade Runner (1982). | F27: Señalización ? | G27: 50000
A28: Costos fijos mensuales: | B28: ='Costos Fijos'!B12 -> 1914900 | D28: Mercedes Sosa y LA FANIA. Volver a los 17 | F28: Extintor | G28: 30000
A29: Margen promedio por prenda: | B29: =IFERROR(AVERAGE(Inventario!E5:E212),0) -> 0.51927438 | D29: Taxi Driver | F29: Decoración y extras | G29: 150000
A30: Precio promedio venta: | B30: =IFERROR(AVERAGE(Inventario!D5:D212),0) -> 107806.12 | D30: Fight Club
A31: Prendas/mes para equilibrio: | B31: =IFERROR(ROUNDUP(B28/(B30*B29),0),0) -> 35 | D31: Scarface | F31: TOTAL | G31: =+SUM(G3:G29) -> 3330000
A32: Prendas/día para equilibrio: | B32: =ROUNDUP(B31/26,0) -> 2 | D32: Vendedora de Rosas
D33: Notorius BIG
A34: RESUMEN FINANCIERO | D34: Celia Cruz
A35: Total deudas | D35: Mike Tyson
A36: Total aportes socios | D36: Principe de Bel Air
D37: Jackass
A38: HORARIOS | D38: Friends
A39: Encargado | B39: Horas Semanales | C39: Días | D39: MTV
A40: JP | B40: =4.5*5 -> 22.5 | C40: L-V 2:30 a 7pm | D40: Play Station 1
...

Sheet Inventario
A1: INVENTARIO | E1: Total Stock: | F1: Valor Costo: | G1: Valor Venta:
E2: =SUM(G5:G1012) -> 184 | F2: =SUMPRODUCT(C5:C1012,G5:G1012) -> 9858000 | G2: =SUMPRODUCT(D5:D1012,G5:G1012) -> 19460000
F3: =SUM(F5:F306) -> 184 | G3: =SUM(G5:G306) -> 184
A4: SKU | B4: Producto | C4: Costo | D4: Precio Venta | E4: Margen % | F4: Entradas | G4: Stock Actual | H4: Notas
A5: CAM-OVS-NEG-S | B5: Camisa Oversize Peruana S Negro | C5: 37000 | D5: 75000 | E5: =IF(D5>0,(D5-C5)/D5,0) -> 0.50666667 | F5: 0 | G5: 0 | H5: BASICO
A6: CAM-OVS-NEG-M | B6: Camisa Oversize Peruana M Negro | C6: 37000 | D6: 75000 | E6: =IF(D6>0,(D6-C6)/D6,0) -> 0.50666667 | F6: 0 | G6: 0 | H6: BASICO
A7: CAM-OVS-NEG-L | B7: Camisa Oversize Peruana L Negro | C7: 37000 | D7: 75000 | E7: =IF(D7>0,(D7-C7)/D7,0) -> 0.50666667 | F7: 0 | G7: 0 | H7: BASICO
A8: CAM-OVS-NEG-XL | B8: Camisa Oversize Peruana XL Negro | C8: 37000 | D8: 75000 | E8: =IF(D8>0,(D8-C8)/D8,0) -> 0.50666667 | F8: 0 | G8: 0 | H8: BASICO
A9: CAM-OVS-BLA-S | B9: Camisa Oversize Peruana S Blanco | C9: 37000 | D9: 75000 | E9: =IF(D9>0,(D9-C9)/D9,0) -> 0.50666667 | F9: 0 | G9: 0 | H9: BASICO
A10: CAM-OVS-BLA-M | B10: Camisa Oversize Peruana M Blanco | C10: 37000 | D10: 75000 | E10: =IF(D10>0,(D10-C10)/D10,0) -> 0.50666667 | F10: 0 | G10: 0 | H10: BASICO
A11: CAM-OVS-BLA-L | B11: Camisa Oversize Peruana L Blanco | C11: 37000 | D11: 75000 | E11: =IF(D11>0,(D11-C11)/D11,0) -> 0.50666667 | F11: 0 | G11: 0 | H11: BASICO
A12: CAM-OVS-BLA-XL | B12: Camisa Oversize Peruana XL Blanco | C12: 37000 | D12: 75000 | E12: =IF(D12>0,(D12-C12)/D12,0) -> 0.50666667 | F12: 0 | G12: 0 | H12: BASICO
A13: CAM-OVS-PER-S | B13: Camisa Oversize Peruana S Perla | C13: 37000 | D13: 75000 | E13: =IF(D13>0,(D13-C13)/D13,0) -> 0.50666667 | F13: 0 | G13: 0 | H13: BASICO
A14: CAM-OVS-PER-M | B14: Camisa Oversize Peruana M Perla | C14: 37000 | D14: 75000 | E14: =IF(D14>0,(D14-C14)/D14,0) -> 0.50666667 | F14: 0 | G14: 0 | H14: BASICO
A15: CAM-OVS-PER-L | B15: Camisa Oversize Peruana L Perla | C15: 37000 | D15: 75000 | E15: =IF(D15>0,(D15-C15)/D15,0) -> 0.50666667 | F15: 0 | G15: 0 | H15: BASICO
A16: CAM-OVS-PER-XL | B16: Camisa Oversize Peruana XL Perla | C16: 37000 | D16: 75000 | E16: =IF(D16>0,(D16-C16)/D16,0) -> 0.50666667 | F16: 0 | G16: 0 | H16: BASICO
... A38: HOOD-ACID-L | B38: Hoodie L Acid Wash Gris | C38: 120000 | D38: 200000 | E38: =IF(D38>0,(D38-C38)/D38,0) -> 0.4 | F38: 12 | G38: 12 | H38: BASICO
A39: CHOM-NEG-S | B39: Chompa Capucha S Negro | C39: ='Pedidos Proveedores'!$E$3 -> 90000 | D39: 200000 | E39: =IF(D39>0,(D39-C39)/D39,0) -> 0.55 | F39: 0 | G39: 0 | H39: BASICO
A40: CHOM-NEG-M | B40: Chompa Capucha M Negro | C40: ='Pedidos Proveedores'!$E$3 -> 90000 | D40: 200000 | E40: =IF(D40>0,(D40-C40)/D40,0) -> 0.55 | F40: 0 | G40: 0 | H40: BASICO
A41: CHOM-NEG-L | B41: Chompa Capucha L Negro | C41: ='Pedidos Proveedores'!$E$3 -> 90000 | D41: 200000 | E41: =IF(D41>0,(D41-C41)/D41,0) -> 0.55 | F41: 0 | G41: 0 | H41: BASICO
A42: CHOM-PER-S | B42: Chompa Capucha S Perla | C42: ='Pedidos Proveedores'!$E$3 -> 90000 | D42: 200000 | E42: =IF(D42>0,(D42-C42)/D42,0) -> 0.55 | F42: 0 | G42: 0 | H42: BASICO
A43: CHOM-PER-M | B43: Chompa Capucha M Perla | C43: ='Pedidos Proveedores'!$E$3 -> 90000 | D43: 200000 | E43: =IF(D43>0,(D43-C43)/D43,0) -> 0.55 | F43: 0 | G43: 0 | H43: BASICO
A44: CHOM-PER-L | B44: Chompa Capucha L Perla | C44: ='Pedidos Proveedores'!$E$3 -> 90000 | D44: 200000 | E44: =IF(D44>0,(D44-C44)/D44,0) -> 0.55 | F44: 4 | G44: 4 | H44: BASICO
A45: CHOM-VERD-S | B45: Chompa Capucha S Verde Botella | C45: ='Pedidos Proveedores'!$E$3 -> 90000 | D45: 200000 | E45: =IF(D45>0,(D45-C45)/D45,0) -> 0.55 | F45: 0 | G45: 0 | H45: BASICO
A46: CHOM-VERD-M | B46: Chompa Capucha M Verde Botella | C46: ='Pedidos Proveedores'!$E$3 -> 90000 | D46: 200000 | E46: =IF(D46>0,(D46-C46)/D46,0) -> 0.55 | F46: 0 | G46: 0 | H46: BASICO
A47: CHOM-VERD-L | B47: Chompa Capucha L Verde Botella | C47: ='Pedidos Proveedores'!$E$3 -> 90000 | D47: 200000 | E47: =IF(D47>0,(D47-C47)/D47,0) -> 0.55 | F47: 0 | G47: 0 | H47: BASICO
A48: CHOM-PLOM-S | B48: Chompa Capucha S Plomo Plata | C48: ='Pedidos Proveedores'!$E$3 -> 90000 | D48: 200000 | E48: =IF(D48>0,(D48-C48)/D48,0) -> 0.55 | F48: 0 | G48: 0 | H48: BASICO
A49: CHOM-PLOM-M | B49: Chompa Capucha M Plomo Plata | C49: ='Pedidos Proveedores'!$E$3 -> 90000 | D49: 200000 | E49: =IF(D49>0,(D49-C49)/D49,0) -> 0.55 | F49: 0 | G49: 0 | H49: BASICO
A50: CHOM-PLOM-L | B50: Chompa Capucha L Plomo Plata | C50: ='Pedidos Proveedores'!$E$3 -> 90000 | D50: 200000 | E50: =IF(D50>0,(D50-C50)/D50,0) -> 0.55 | F50: 0 | G50: 0 | H50: BASICO
A51: BUZ-OVS-NEG-M | B51: Buzo Cuello Redondo Oversized M Negro | C51: 55000 | D51: 120000 | E51: =IF(D51>0,(D51-C51)/D51,0) -> 0.54166667 | F51: 2 | G51: 2 | H51: BASICO
A52: BUZ-OVS-NEG-L | B52: Buzo Cuello Redondo Oversized L Negro | C52: 55000 | D52: 120000 | E52: =IF(D52>0,(D52-C52)/D52,0) -> 0.54166667 | F52: 4 | G52: 4 | H52: BASICO
A53: BUZ-OVS-NEG-XL | B53: Buzo Cuello Redondo Oversized XL Negro | C53: 55000 | D53: 120000 | E53: =IF(D53>0,(D53-C53)/D53,0) -> 0.54166667 | F53: 4 | G53: 4 | H53: BASICO
A54: BUZ-OVS-BEIG-M | B54: Buzo Cuello Redondo Oversized M Beige | C54: 55000 | D54: 120000 | E54: =IF(D54>0,(D54-C54)/D54,0) -> 0.54166667 | F54: 2 | G54: 2 | H54: BASICO
A55: BUZ-OVS-BEIG-L | B55: Buzo Cuello Redondo Oversized L Beige | C55: 55000 | D55: 120000 | E55: =IF(D55>0,(D55-C55)/D55,0) -> 0.54166667 | F55: 2 | G55: 2 | H55: BASICO
A56: BUZ-OVS-BEIG-XL | B56: Buzo Cuello Redondo Oversized XL Beige | C56: 55000 | D56: 120000 | E56: =IF(D56>0,(D56-C56)/D56,0) -> 0.54166667 | F56: 2 | G56: 2 | H56: BASICO
A57: BUZ-OVS-NEG-2XL | B57: Buzo Cuello Redondo Oversized 2XL Negro | C57: 55000 | D57: 120000 | E57: =IF(D57>0,(D57-C57)/D57,0) -> 0.54166667 | F57: 2 | G57: 2 | H57: BASICO
A58: BUZ-OVS-BEIG-2XL | B58: Buzo Cuello Redondo Oversized 2XL Beige | C58: 55000 | D58: 120000 | E58: =IF(D58>0,(D58-C58)/D58,0) -> 0.54166667 | F58: 2 | G58: 2 | H58: BASICO
A59: BUZ-OVS-CAF-L | B59: Buzo Cuello Redondo Oversized L Café | C59: 55000 | D59: 120000 | E59: =IF(D59>0,(D59-C59)/D59,0) -> 0.54166667 | F59: 2 | G59: 2 | H59: BASICO
A60: BUZ-OVS-CAF-XL | B60: Buzo Cuello Redondo Oversized XL Café | C60: 55000 | D60: 120000 | E60: =IF(D60>0,(D60-C60)/D60,0) -> 0.54166667 | F60: 2 | G60: 2 | H60: BASICO
A61: JOG-NEG-M | B61: Jogger Largo M Negro | C61: 55000 | D61: 100000 | E61: =IF(D61>0,(D61-C61)/D61,0) -> 0.45 | F61: 4 | G61: 4 | H61: BASICO
...

Sheet Caja Diaria
A1: Fecha | B1: Efectivo Inicio | C1: Ventas Efectivo | D1: Ventas Datáfono | E1: Ventas Transf. | F1: Gastos Efectivo | G1: Efectivo Cierre | H1: Diferencia | I1: Notas
A2: 46067 | B2: 0 | C2: 0 | D2: 0 | E2: 120000 | F2: 0 | G2: =B2+C2-F2 -> 0 | H2: =G2-(B2+C2-F2) -> 0 | I2: Claudia Ramírez debe 200.000 de Hoodie Acid Wash M
G3: =B3+C3-F3 -> 0 | H3: =G3-(B3+C3-F3) -> 0
G4: =B4+C4-F4 -> 0 | H4: =G4-(B4+C4-F4) -> 0
G5: =B5+C5-F5 -> 0 | H5: =G5-(B5+C5-F5) -> 0
G6: =B6+C6-F6 -> 0 | H6: =G6-(B6+C6-F6) -> 0
G7: =B7+C7-F7 -> 0 | H7: =G7-(B7+C7-F7) -> 0
G8: =B8+C8-F8 -> 0 | H8: =G8-(B8+C8-F8) -> 0
G9: =B9+C9-F9 -> 0 | H9: =G9-(B9+C9-F9) -> 0
G10: =B10+C10-F10 -> 0 | H10: =G10-(B10+C10-F10) -> 0
G11: =B11+C11-F11 -> 0 | H11: =G11-(B11+C11-F11) -> 0
G12: =B12+C12-F12 -> 0 | H12: =G12-(B12+C12-F12) -> 0
G13: =B13+C13-F13 -> 0 | H13: =G13-(B13+C13-F13) -> 0
G14: =B14+C14-F14 -> 0 | H14: =G14-(B14+C14-F14) -> 0
... G61: =B61+C61-F61 -> 0 | H61: =G61-(B61+C61-F61) -> 0

Sheet Ventas
A1: Fecha | B1: SKU | C1: Producto | D1: Costo | E1: Precio Venta | F1: Método Pago | G1: Cliente | H1: Notas | K1: Efectivo
A2: 46067 | B2: =Inventario!A76 -> CHA-VERNEG-M | C2: =IFERROR(VLOOKUP(B2,Inventario!A:C,2,FALSE()),"") -> Chaqueta Cortavientos M Verde Botella/Negro | D2: =IFERROR(VLOOKUP(B2,Inventario!A:C,3,FALSE()),"") -> 40000 | E2: =IFERROR(VLOOKUP(B2,Inventario!A:D,4,FALSE()),"") -> 120000 | F2: Transferencia | G2: Edison | K2: Transferencia
A3: 46067 | B3: =Inventario!A38 -> HOOD-ACID-L | C3: =IFERROR(VLOOKUP(B3,Inventario!A:C,2,FALSE()),"") -> Hoodie L Acid Wash Gris | D3: =IFERROR(VLOOKUP(B3,Inventario!A:C,3,FALSE()),"") -> 120000 | E3: =IFERROR(VLOOKUP(B3,Inventario!A:D,4,FALSE()),"") -> 200000 | F3: Crédito | G3: Claudia Ramírez | H3: Se debe completo | K3: Datáfono
C4: =IFERROR(VLOOKUP(B4,Inventario!A:C,2,FALSE()),"") | D4: =IFERROR(VLOOKUP(B4,Inventario!A:C,3,FALSE()),"") | E4: =IFERROR(VLOOKUP(B4,Inventario!A:D,4,FALSE()),"") | K4: Crédito
C5: =IFERROR(VLOOKUP(B5,Inventario!A:C,2,FALSE()),"") | D5: =IFERROR(VLOOKUP(B5,Inventario!A:C,3,FALSE()),"") | E5: =IFERROR(VLOOKUP(B5,Inventario!A:D,4,FALSE()),"")
C6: =IFERROR(VLOOKUP(B6,Inventario!A:C,2,FALSE()),"") | D6: =IFERROR(VLOOKUP(B6,Inventario!A:C,3,FALSE()),"") | E6: =IFERROR(VLOOKUP(B6,Inventario!A:D,4,FALSE()),"")
C7: =IFERROR(VLOOKUP(B7,Inventario!A:C,2,FALSE()),"") | D7: =IFERROR(VLOOKUP(B7,Inventario!A:C,3,FALSE()),"") | E7: =IFERROR(VLOOKUP(B7,Inventario!A:D,4,FALSE()),"")
C8: =IFERROR(VLOOKUP(B8,Inventario!A:C,2,FALSE()),"") | D8: =IFERROR(VLOOKUP(B8,Inventario!A:C,3,FALSE()),"") | E8: =IFERROR(VLOOKUP(B8,Inventario!A:D,4,FALSE()),"")
C9: =IFERROR(VLOOKUP(B9,Inventario!A:C,2,FALSE()),"") | D9: =IFERROR(VLOOKUP(B9,Inventario!A:C,3,FALSE()),"") | E9: =IFERROR(VLOOKUP(B9,Inventario!A:D,4,FALSE()),"")
C10: =IFERROR(VLOOKUP(B10,Inventario!A:C,2,FALSE()),"") | D10: =IFERROR(VLOOKUP(B10,Inventario!A:C,3,FALSE()),"") | E10: =IFERROR(VLOOKUP(B10,Inventario!A:D,4,FALSE()),"")
C11: =IFERROR(VLOOKUP(B11,Inventario!A:C,2,FALSE()),"") | D11: =IFERROR(VLOOKUP(B11,Inventario!A:C,3,FALSE()),"") | E11: =IFERROR(VLOOKUP(B11,Inventario!A:D,4,FALSE()),"")
C12: =IFERROR(VLOOKUP(B12,Inventario!A:C,2,FALSE()),"") | D12: =IFERROR(VLOOKUP(B12,Inventario!A:C,3,FALSE()),"") | E12: =IFERROR(VLOOKUP(B12,Inventario!A:D,4,FALSE()),"")
C13: =IFERROR(VLOOKUP(B13,Inventario!A:C,2,FALSE()),"") | D13: =IFERROR(VLOOKUP(B13,Inventario!A:C,3,FALSE()),"") | E13: =IFERROR(VLOOKUP(B13,Inventario!A:D,4,FALSE()),"")
C14: =IFERROR(VLOOKUP(B14,Inventario!A:C,2,FALSE()),"") | D14: =IFERROR(VLOOKUP(B14,Inventario!A:C,3,FALSE()),"") | E14: =IFERROR(VLOOKUP(B14,Inventario!A:D,4,FALSE()),"")
C15: =IFERROR(VLOOKUP(B15,Inventario!A:C,2,FALSE()),"") | D15: =IFERROR(VLOOKUP(B15,Inventario!A:C,3,FALSE()),"") | E15: =IFERROR(VLOOKUP(B15,Inventario!A:D,4,FALSE()),"")
C16: =IFERROR(VLOOKUP(B16,Inventario!A:C,2,FALSE()),"") | D16: =IFERROR(VLOOKUP(B16,Inventario!A:C,3,FALSE()),"") | E16: =IFERROR(VLOOKUP(B16,Inventario!A:D,4,FALSE()),"")
... C51: =IFERROR(VLOOKUP(B51,Inventario!A:C,2,FALSE()),"") | D51: =IFERROR(VLOOKUP(B51,Inventario!A:C,3,FALSE()),"") | E51: =IFERROR(VLOOKUP(B51,Inventario!A:D,4,FALSE()),"")
A55: RESUMEN VENTAS
A56: Total ventas: | B56: =COUNTA(B2:B50) -> 2
A57: Ingresos: | B57: =SUM(E2:E50) -> 320000
A58: Costo mercancía: | B58: =SUM(D2:D50) -> 160000
A59: Margen bruto: | B59: =B57-B58 -> 160000

Sheet Costos Fijos
A1: COSTOS FIJOS MENSUALES
A3: CONCEPTO | B3: MONTO (COP) | C3: NOTAS
A4: Arriendo mensual | B4: 1210000
A5: Servicios públicos | B5: 250000 | C5: Estimado
A6: Internet | B6: 69000 | C6: Primeros dos meses $34.500
A7: Persona punto de venta | C7: Por ahora atienden socios (Una vez haya persona vale 3.000.000 mensual)
A8: Digitales | B8: =100000+53000 -> 153000 | C8: Marketing, IA (Shopify, AI Finder, ManyChat, Google Workspace, Hostinger, Freepik, Mockey) - esas 7 a futuro - Fijos hoy: Shopify, Google Workspace (Dominio)
A9: Seguros | B9: 80000
A10: Imprevistos | B10: =SUM(B4:B6)*0.1 -> 152900 | C10: 10% del total
A12: TOTAL | B12: =SUM(B4:B10) -> 1914900

Sheet Gastos
A1: Fecha | B1: Categoría | C1: Monto | D1: Descripción | E1: Método Pago | F1: Responsable | G1: Notas | I1: CATEGORÍAS DISPONIBLES: | L1: RESPONSABLES | M1: TOTAL | O1: Rubro | P1: Fecha Periódica
A2: 45992 | B2: Arriendo | C2: 404000 | D2: Pago arriendo Diciembre | E2: Transferencia | F2: KATHE | I2: Arriendo | J2: =SUMIF(B:B,I2,C:C) -> 3636000 | L2: ORVANN | M2: =SUMIF($F$2:$F$1006,L2,$C$2:$C$1006) -> 0 | O2: Pago Arriendo | P2: 1 de cada mes
A3: 45992 | B3: Arriendo | C3: 404000 | D3: Pago arriendo Diciembre | E3: Transferencia | F3: MILE | I3: Servicios (Agua, Luz, Gas) | J3: =SUMIF(B:B,I3,C:C) -> 0 | L3: KATHE | M3: =SUMIF($F$2:$F$1006,L3,$C$2:$C$1006) -> 5916090 | N3: =M3-890000 -> 5026090 | O3: Pago Servicios
A4: 45992 | B4: Arriendo | C4: 404000 | D4: Pago arriendo Diciembre | E4: Transferencia | F4: JP | I4: Internet | J4: =SUMIF(B:B,I4,C:C) -> 0 | L4: MILE | M4: =SUMIF($F$2:$F$1006,L4,$C$2:$C$1006) -> 5779090 | N4: =M4-890000 -> 4889090 | O4: Pago Internet
A5: 45998 | B5: Dotación local | C5: 2000000 | D5: Pago arreglo Local | E5: Transferencia | F5: KATHE | I5: Nómina/Vendedor | J5: =SUMIF(B:B,I5,C:C) -> 0 | L5: JP | M5: =SUMIF($F$2:$F$1006,L5,$C$2:$C$1006) -> 5751890 | N5: =M5-890000 -> 4861890 | O5: Pago Shopify
A6: 45998 | B6: Dotación local | C6: 2000000 | D6: Pago arreglo Local | E6: Transferencia | F6: MILE | I6: Contador | J6: =SUMIF(B:B,I6,C:C) -> 0 | O6: Pago Correo Corporativo | P6: 10 de cada mes
A7: 45998 | B7: Dotación local | C7: 2000000 | D7: Pago arreglo Local | E7: Transferencia | F7: JP | I7: Publicidad/Marketing | J7: =SUMIF(B:B,I7,C:C) -> 224746
A8: 46007 | B8: Dotación local | C8: 117000 | D8: Lavamanos | E8: Transferencia | F8: JP | I8: Empaque (Bolsas, Etiquetas) | J8: =SUMIF(B:B,I8,C:C) -> 0 | L8: Arreglo local | M8: 8160000
A9: 46007 | B9: Dotación local | C9: 117000 | D9: Lavamanos | E9: Transferencia | F9: MILE | I9: Aseo/Mantenimiento | J9: =SUMIF(B:B,I9,C:C) -> 157000 | L9: Faltantes | M9: 160000
A10: 46007 | B10: Dotación local | C10: 117000 | D10: Lavamanos | E10: Transferencia | F10: KATHE | I10: Transporte | J10: =SUMIF(B:B,I10,C:C) -> 67100
A11: 46008 | B11: Dotación local | C11: 18000 | D11: Percheros pequeños | E11: Transferencia | F11: JP | I11: Comisiones datáfono | J11: =SUMIF(B:B,I11,C:C) -> 0 | L11: Aporte por socio | M11: 2720000
A12: 46008 | B12: Dotación local | C12: 18000 | D12: Percheros pequeños | E12: Transferencia | F12: MILE | I12: Ilustraciones/Diseño | J12: =SUMIF(B:B,I12,C:C) -> 420000
A13: 46008 | B13: Dotación local | C13: 18000 | D13: Percheros pequeños | E13: Transferencia | F13: KATHE | I13: Dotación local | J13: =SUMIF(B:B,I13,C:C) -> 9376100
A14: 46018 | B14: Dotación local | C14: 500000 | D14: Pago arreglo Local | E14: Transferencia | F14: MILE | I14: Imprevistos | J14: =SUMIF(B:B,I14,C:C) -> 0
A15: 46018 | B15: Dotación local | C15: 100000 | D15: Pago arreglo Local | E15: Transferencia | F15: JP | I15: Mercancía | J15: =SUMIF(B:B,I15,C:C) -> 3566124
A16: 46023 | B16: Arriendo | C16: 404000 | D16: Pago arriendo Enero | E16: Transferencia | F16: KATHE | I16: Otro | J16: =SUMIF(B:B,I16,C:C) -> 0
A17: 46023 | B17: Arriendo | C17: 404000 | D17: Pago arriendo Enero | E17: Transferencia | F17: JP
A18: 46023 | B18: Arriendo | C18: 404000 | D18: Pago arriendo Enero | E18: Transferencia | F18: MILE
A19: 46024 | B19: Publicidad/Marketing | C19: 59682 | D19: Pago mensualidad Freepick y Mockey | E19: Transferencia | F19: JP
A20: 46024 | B20: Publicidad/Marketing | C20: 59682 | D20: Pago mensualidad Freepick y Mockey | E20: Transferencia | F20: KATHE
A21: 46024 | B21: Publicidad/Marketing | C21: 59682 | D21: Pago mensualidad Freepick y Mockey | E21: Transferencia | F21: MILE
A22: 46032 | B22: Dotación local | C22: 287000 | D22: Espejo, Toldo y Cámaras | E22: Transferencia | F22: JP
A23: 46032 | B23: Dotación local | C23: 287000 | D23: Espejo, Toldo y Cámaras | E23: Transferencia | F23: KATHE
A24: 46032 | B24: Dotación local | C24: 287000 | D24: Espejo, Toldo y Cámaras | E24: Transferencia | F24: MILE
A25: 46037 | B25: Dotación local | C25: 30000 | D25: Adicional espejo | E25: Transferencia | F25: MILE
A26: 46037 | B26: Dotación local | C26: 30000 | D26: Adicional espejo | E26: Transferencia | F26: JP
A27: 46037 | B27: Dotación local | C27: 30000 | D27: Adicional espejo | E27: Transferencia | F27: KATHE
A28: 45674 | B28: Dotación local | C28: 220000 | D28: Pago arreglo Local | E28: Transferencia | F28: MILE
... A40: 46059 | B40: Dotación local | C40: 400000 | D40: Pago arreglo Local | E40: Transferencia | F40: JP
A41: 46062 | B41: Mercancía | C41: =2670000/3 -> 890000 | D41: Mercancía Your Brand | E41: Datáfono | F41: MILE | G41: Pago con TC de JP (Pendiente pago)
A42: 46062 | B42: Mercancía | C42: =C41 -> 890000 | D42: Mercancía Your Brand | E42: Datáfono | F42: KATHE | G42: Pago con TC de JP (Pendiente pago)
A43: 46062 | B43: Mercancía | C43: =C42 -> 890000 | D43: Mercancía Your Brand | E43: Datáfono | F43: JP
A44: 46057 | B44: Mercancía | C44: 80000 | D44: Mercancía Your Brand | E44: Transferencia | F44: KATHE
A45: 46057 | B45: Mercancía | C45: 80000 | D45: Mercancía Your Brand | E45: Transferencia | F45: MILE
A46: 46057 | B46: Mercancía | C46: 80000 | D46: Mercancía Your Brand | E46: Transferencia | F46: JP
A47: 46062 | B47: Transporte | C47: 20000 | D47: Domicilio Mercancía Your Brand | E47: Transferencia | F47: KATHE
A48: 46063 | B48: Publicidad/Marketing | C48: 36700 | D48: Compra Dominio orvann.co | E48: Transferencia | F48: JP
A49: 46064 | B49: Publicidad/Marketing | C49: 9000 | D49: Compra Dominio orvann.co | E49: Transferencia | F49: KATHE
A50: 46067 | B50: Transporte | C50: 19100 | D50: Transporte mercancía Auren | E50: Transferencia | F50: JP
A51: 45693 | B51: Mercancía | C51: 218708 | D51: Marquillas y Etiquetas | E51: Transferencia | F51: KATHE
...

Sheet Pedidos Proveedores
A1: Fecha Pedido | B1: Proveedor | C1: Descripción | D1: Unidades | E1: Costo Unit. | F1: Total | G1: Estado Pago | H1: Fecha Pago | I1: Notas | L1: Pendiente | M1: =SUMIF($G$2:$G$15,L1,$F$2:$F$15) -> 9618000 | Q1: Precios Proveedores
A2: 45692 | B2: YOUR BRAND | C2: Hoodie L | D2: 2 | E2: 120000 | F2: =D2*E2 -> 240000 | G2: Pagado | H2: 46057 | I2: 2 Acid Wash gris | L2: Pagado | M2: =SUMIF($G$2:$G$15,L2,$F$2:$F$15) -> 240000 | Q2: AUREN | R2: Precio
A3: 45692 | B3: YOUR BRAND | C3: Chompa 320gr Talla L | D3: 4 | E3: 90000 | F3: =D3*E3 -> 360000 | G3: Pendiente | I3: Crédito JP - 4 Perla | L3: Crédito | M3: =SUMIF($G$2:$G$15,L3,$F$2:$F$15) -> 0 | Q3: Regular | R3: 32000
A4: 46062 | B4: YOUR BRAND | C4: Hoodie L | D4: 10 | E4: 120000 | F4: =D4*E4 -> 1200000 | G4: Pendiente | I4: Crédito JP - 10 Acid Wash gris | Q4: Oversize | R4: 35000
A5: 46062 | B5: YOUR BRAND | C5: Camiseta Boxy Fit 320gr | D5: 30 | E5: 37000 | F5: =D5*E5 -> 1110000 | G5: Pendiente | I5: Crédito JP - 10 negras, 10 blancas, 10 plomo plata | Q5: Buso regular | R5: 50000
A6: 46056 | B6: BRACOR | C6: Camiseta Réplica Y/Out 1.1 | D6: 8 | E6: 60000 | F6: =D6*E6 -> 480000 | G6: Pendiente | Q6: Buso oversize | R6: 55000
A7: 46056 | B7: BRACOR | C7: Camiseta Réplica 1.1 | D7: 22 | E7: 54000 | F7: =D7*E7 -> 1188000 | G7: Pendiente | Q7: Pantaloneta | R7: 45000
A8: 46067 | B8: AUREN | C8: Chaqueta Cortavientos | D8: 36 | E8: 40000 | F8: =D8*E8 -> 1440000 | G8: Pendiente | I8: 24 Chaquetas 1 Color y 12 Chaquetas Bicolor | Q8: Jogger | R8: 55000
A9: 46067 | B9: AUREN | C9: Pantalonetas | D9: 12 | E9: 45000 | F9: =D9*E9 -> 540000 | G9: Pendiente | I9: 12 Pantalonetas (Negras, Beige y Café) | Q9: Sudadera bota recta | R9: 55000
A10: 46067 | B10: AUREN | C10: Sudadera Bota Recta | D10: 12 | E10: 55000 | F10: =D10*E10 -> 660000 | G10: Pendiente | I10: 12 Sudaderas (Negras, Beige y Café) | Q10: Chompa | R10: 75000
A11: 46067 | B11: AUREN | C11: Jogger | D11: 24 | E11: 55000 | F11: =D11*E11 -> 1320000 | G11: Pendiente | I11: 12 Jogger (Negras, Beige y Café) | Q11: Chaquetas cortavientos | R11: 40000
A12: 46067 | B12: AUREN | C12: Buso Oversized | D12: 24 | E12: 55000 | F12: =D12*E12 -> 1320000 | G12: Pendiente | I12: 24 Busos Oversized (Negro, Beige y Café) | Q12: Sudadera cortavientos | R12: 32000
F13: =D13*E13 -> 0 | Q13: Chaqueta reflectiva | R13: 50000
F14: =D14*E14 -> 0
Q15: ETIQUETAS / MARQUILLAS / EMPAQUES
A16: TOTAL PEDIDOS | D16: =SUM(D2:D14) -> 184 | F16: =SUM(F2:F14) -> 9858000 | Q16: Bolsas buenas | R16: 600
Q17: bolsa sencilla | R17: 150

Sheet Análisis Precios
A1: ANÁLISIS DE COSTO REAL POR TIPO DE PRENDA
A2: Incluye: Prenda + Estampado + Etiquetas + Empaque
A4: COSTOS ADICIONALES (EDITAR EN AZUL) | F4: Siempre precio llevando los diseños listos
A5: Concepto | B5: 1-10 uds | C5: 11-50 uds | D5: 51-100 uds | E5: Más de 100 | F5: Notas
A6: Estampado DTF pequeño (pecho) | B6: =25000/8 -> 3125 | C6: =25000/10 -> 2500 | D6: =25000/10 -> 2500 | E6: =25000/12 -> 2083.3333 | F6: Se vende por metro. El metro vale aproximadamente 25.000. Salen tamaño (Aprox 57 cm de ancho): punto corazon (Logo pequeño), media carta (Logo estandar tipo clemont), carta (Figura tamaño carta), oficio y tabloide (Casi estampado completo). Salen unos 100 punto corazón, unas 15 media carta, unas 8 carta, unas 6 oficio y 2 tabloides.
A7: Estampado DTF grande (espalda) | B7: =25000/2 -> 12500 | C7: =25000/3 -> 8333.3333 | D7: =25000/3 -> 8333.3333 | E7: =25000/4 -> 6250 | F7: Llenar después de cotizar
A8: Estampado Serigrafía (1 color) | B8: $8,000 | C8: $5,000 | D8: $3,500 | E8: $2,500 | F8: El metro de vinilo de alta densidad vale aprox 105.000 (sumando el estampado (72.000) plotteado y descolillado (33.000), si se averigua seguro es más barato) - Solo negro, blanco y rojo normalmente / El metro de vinilo vale aprox 80.000 (sumando el estampado (45.000) plotteado y descolillado (35.000), si se averigua seguro es más barato) - Solo negro, blanco y rojo normalmente. Vinilo sale en un solo color, DTF varios. Vinilo queda con un poco de relieve. DTG no se encontró (Proveedor Santiago)
A9: Etiqueta cuello tejida | B9: 1500 | C9: 1000 | D9: 800 | E9: 600 | F9: Mínimo típico: 100 uds
A10: Hang tag (etiqueta colgante) | B10: 1200 | C10: $800 | D10: $600 | E10: $400 | F10: Con diseño e hilo
A11: Bolsa papel con logo | B11: 1500 | C11: 1000 | D11: 800 | E11: 800
A12: Bolsa premium | B12: 3000 | C12: 3000 | D12: 2500 | E12: 2000 | F12: Bolsa Premium
A13: Sticker logo | B13: 500 | C13: 300 | D13: 200 | E13: 150 | F13: Para sellar bolsa y dejar adentro
A16: COSTO REAL POR TIPO DE PRODUCTO
A17: Tipo Prenda | B17: Costo Base AUREN | C17: Estampado | D17: Etiquetas | E17: Empaque | F17: COSTO TOTAL | G17: Precio Venta Sugerido | H17: Margen %
A18: Camisa Básica (sin estampar) | B18: 37000 | C18: 0 | D18: =$B$9+$B$10 -> 2700 | E18: =$B$11+$B$12+$B$13 -> 5000 | F18: =SUM(B18:E18) -> 44700 | G18: 80000 | H18: =IF(G18>0,(G18-F18)/G18,0) -> 0.44125
A19: Camisa Estampada Pecho | B19: 37000 | C19: =B6 -> 3125 | D19: =$B$9+$B$10 -> 2700 | E19: =$B$11+$B$12+$B$13 -> 5000 | F19: =SUM(B19:E19) -> 47825 | G19: 80000 | H19: =IF(G19>0,(G19-F19)/G19,0) -> 0.4021875
A20: Camisa Estampada Espalda | B20: 37000 | C20: =B7 -> 12500 | D20: =$B$9+$B$10 -> 2700 | E20: =$B$11+$B$12+$B$13 -> 5000 | F20: =SUM(B20:E20) -> 57200 | G20: 80000 | H20: =IF(G20>0,(G20-F20)/G20,0) -> 0.285
A21: Camisa Estampada Full (pecho+espalda) | B21: 37000 | C21: =C19+C20 -> 15625 | D21: =$B$9+$B$10 -> 2700 | E21: =$B$11+$B$12+$B$13 -> 5000 | F21: =SUM(B21:E21) -> 60325 | G21: 80000 | H21: =IF(G21>0,(G21-F21)/G21,0) -> 0.2459375
A22: Chompa Capucha Básica | B22: 76000 | C22: $0 | D22: =$B$9+$B$10 -> 2700 | E22: =$B$11+$B$12+$B$13 -> 5000 | F22: =SUM(B22:E22) -> 83700 | G22: 120000 | H22: =IF(G22>0,(G22-F22)/G22,0) -> 0.3025
A23: Chompa Capucha Estampada | B23: 76000 | C23: =C21 -> 15625 | D23: =$B$9+$B$10 -> 2700 | E23: =$B$11+$B$12+$B$13 -> 5000 | F23: =SUM(B23:E23) -> 99325 | G23: 130000 | H23: =IF(G23>0,(G23-F23)/G23,0) -> 0.23596154
A24: Buzo Cuello Redondo Básico | B24: 56000 | C24: $0 | D24: =$B$9+$B$10 -> 2700 | E24: =$B$11+$B$12+$B$13 -> 5000 | F24: =SUM(B24:E24) -> 63700 | G24: 100000 | H24: =IF(G24>0,(G24-F24)/G24,0) -> 0.363
A25: Buzo Estampado | B25: 56000 | C25: =C23 -> 15625 | D25: =$B$9+$B$10 -> 2700 | E25: =$B$11+$B$12+$B$13 -> 5000 | F25: =SUM(B25:E25) -> 79325 | G25: 120000 | H25: =IF(G25>0,(G25-F25)/G25,0) -> 0.33895833
A26: Jogger Básico | B26: 62000 | C26: $0 | D26: =$B$9+$B$10 -> 2700 | E26: =$B$11+$B$12+$B$13 -> 5000 | F26: =SUM(B26:E26) -> 69700 | G26: 100000 | H26: =IF(G26>0,(G26-F26)/G26,0) -> 0.303
A27: Sudadera Bota Recta Básica | B27: 62000 | C27: $0 | D27: =$B$9+$B$10 -> 2700 | E27: =$B$11+$B$12+$B$13 -> 5000 | F27: =SUM(B27:E27) -> 69700 | G27: 100000 | H27: =IF(G27>0,(G27-F27)/G27,0) -> 0.303
A28: Pantaloneta Básica | B28: 49000 | C28: $0 | D28: =$B$9+$B$10 -> 2700 | E28: =$B$11+$B$12+$B$13 -> 5000 | F28: =SUM(B28:E28) -> 56700 | G28: 80000 | H28: =IF(G28>0,(G28-F28)/G28,0) -> 0.29125
A29: Chaqueta Cortavientos Básica | B29: 45000 | C29: $0 | D29: =$B$9+$B$10 -> 2700 | E29: =$B$11+$B$12+$B$13 -> 5000 | F29: =SUM(B29:E29) -> 52700 | G29: 80000 | H29: =IF(G29>0,(G29-F29)/G29,0) -> 0.34125
A30: Chaqueta Cortavientos Estampada | B30: 45000 | C30: =C25 -> 15625 | D30: =$B$9+$B$10 -> 2700 | E30: =$B$11+$B$12+$B$13 -> 5000 | F30: =SUM(B30:E30) -> 68325 | G30: 100000 | H30: =IF(G30>0,(G30-F30)/G30,0) -> 0.31675
A34: ESCENARIOS DE PRECIO DE VENTA - CAMISA ESTAMPADA
A35: Escenario | B35: Costo Total | C35: Precio Venta | D35: Margen $ | E35: Margen % | F35: Comentario
A36: Económico (réplica) | B36: =F21 -> 60325 | C36: 80000 | D36: =C36-B36 -> 19675 | E36: =IF(C36>0,(C36-B36)/C36,0) -> 0.2459375 | F36: Competir con réplicas baratas
A37: Estándar | B37: =F21 -> 60325 | C37: 90000 | D37: =C37-B37 -> 29675 | E37: =IF(C37>0,(C37-B37)/C37,0) -> 0.32972222 | F37: Precio medio del mercado
A38: Premium ORVANN | B38: =F21 -> 60325 | C38: 110000 | D38: =C38-B38 -> 49675 | E38: =IF(C38>0,(C38-B38)/C38,0) -> 0.45159091 | F38: Marca propia, diseño exclusivo
A39: Ultra Premium (edición limitada) | B39: =F21*1.1 -> 66357.5 | C39: 140000 | D39: =C39-B39 -> 73642.5 | E39: =IF(C39>0,(C39-B39)/C39,0) -> 0.52601786 | F39: Colección especial, empaque VHS/Vinilo
A42: NOTAS IMPORTANTES:
A43: Los precios en AZUL son inputs
A44: Para réplicas (Clemont, etc): menor margen pero mayor volumen
A45: Para colecciones ORVANN: mayor margen, menor volumen, más exclusividad

Sheet Cotizador Compras
A1: COTIZADOR DE COMPRAS - ORVANN
A3: CATÁLOGO DE PRODUCTOS (Referencia de Costos) | O3: LISTAS DE OPCIONES (Ocultar esta columna)
A4: Tipo Producto | B4: Proveedor | C4: Costo Base | D4: Estampado Pecho | E4: Estampado Espalda | F4: Etiquetas | G4: Empaque | H4: Precio Venta Basica | I4: Precio Venta Estampado Full | J4: Precio Venta Estampado Pecho | O4: Productos | P4: Tallas | Q4: Colores | R4: Estampado
A5: Camisa Oversize | B5: AUREN | C5: 35000 | D5: 3500 | E5: 11000 | F5: 1700 | G5: 1000 | H5: 75000 | I5: 130000 | J5: 100000 | O5: Camisa Oversize | P5: S | Q5: Negro | R5: Sin estampar
A6: Camisa Oversize Peruana | B6: YOUR BRAND | C6: 37000 | D6: 3500 | E6: 11000 | F6: 1700 | G6: 1000 | H6: 75000 | I6: 130000 | J6: 100000 | O6: Camisa Oversize Peruana | P6: M | Q6: Blanco | R6: Pecho
A7: Camisa Regular | B7: YOUR BRAND | C7: 37000 | D7: 3500 | E7: 11000 | F7: 1700 | G7: 1000 | H7: 75000 | I7: 130000 | J7: 100000 | O7: Camisa Regular | P7: L | Q7: Plomo Plata | R7: Espalda
A8: Camisa Boxy fit | B8: YOUR BRAND | C8: 37000 | D8: 3500 | E8: 11000 | F8: 1700 | G8: 1000 | H8: 75000 | I8: 130000 | J8: 100000 | O8: Camisa Boxy fit | P8: XL | Q8: Beige | R8: Full (Pecho+Espalda)
A9: Chompa Capucha | B9: YOUR BRAND | C9: 90000 | D9: 3500 | E9: 11000 | F9: 1700 | G9: 1000 | H9: 200000 | I9: 260000 | J9: 230000 | O9: Chompa Capucha | P9: 2XL | Q9: Perla | R9: Especial
A10: Hoodie | B10: YOUR BRAND | C10: 120000 | D10: 3500 | E10: 11000 | F10: 1700 | G10: 1000 | H10: 200000 | I10: 260000 | J10: 230000 | O10: Hoodie | P10: Unica | Q10: Acid Wash Gris
A11: Buzo Cuello Redondo Regular | B11: AUREN | C11: 50000 | D11: 3500 | E11: 11000 | F11: 1700 | G11: 1000 | H11: 120000 | I11: 140000 | J11: 140000 | O11: Buzo Cuello Redondo Regular | Q11: Verde Botella
A12: Buzo Cuello Redondo Oversized | B12: AUREN | C12: 55000 | D12: 3500 | E12: 11000 | F12: 1700 | G12: 1000 | H12: 120000 | I12: 140000 | J12: 140000 | O12: Buzo Cuello Redondo Oversized | Q12: Café
A13: Jogger Largo | B13: AUREN | C13: 55000 | D13: 3500 | E13: 11000 | F13: 1700 | G13: 1000 | H13: 100000 | I13: 100000 | J13: 100000 | O13: Jogger Largo
A14: Sudadera Bota Recta | B14: AUREN | C14: 55000 | D14: 3500 | E14: 11000 | F14: 1700 | G14: 1000 | H14: 90000 | I14: 100000 | J14: 100000 | O14: Sudadera Bota Recta
A15: Pantaloneta | B15: AUREN | C15: 45000 | D15: 3500 | E15: 11000 | F15: 1700 | G15: 1000 | H15: 90000 | I15: 90000 | J15: 90000 | O15: Pantaloneta
A16: Chaqueta Cortavientos | B16: AUREN | C16: 40000 | D16: 3500 | E16: 11000 | F16: 1700 | G16: 1000 | H16: 120000 | I16: 120000 | J16: 120000 | O16: Chaqueta Cortavientos
A17: Sudadera Cortavientos | B17: AUREN | C17: 32000 | D17: 3500 | E17: 11000 | F17: 1700 | G17: 1000 | H17: 65000 | I17: 65000 | J17: 65000 | O17: Sudadera Cortavientos
A18: Gorra | C18: 25000 | D18: 5000 | F18: 1700 | G18: 1000 | H18: 50000 | I18: 65000 | J18: 65000 | O18: Gorra
A19: Camisa Réplica Y/Out | B19: BRACOR | C19: 60000 | G19: 1000 | H19: 75000 | I19: =+'Cotizador Compras'!$H19 -> 75000 | J19: =+'Cotizador Compras'!$H19 -> 75000 | O19: Camisa Réplica White Out
A20: Camisa Réplica 1.1 | B20: BRACOR | C20: 54000 | G20: 1000 | H20: 75000 | I20: =+'Cotizador Compras'!$H20 -> 75000 | J20: =+'Cotizador Compras'!$H20 -> 75000 | O20: Camisa Réplica 1.1
A22: PLANIFICADOR DE COMPRA
A25: Tipo Producto | B25: Talla | C25: Color | D25: Estampado | E25: Cantidad | F25: Provedor | G25: Costo Prenda | H25: Costo Estampado | I25: Costo Etiquetas | J25: Costo Empaque | K25: COSTO TOTAL | L25: Precio Venta Unit. | M25: VENTA TOTAL | N25: Costo Unitario | O25: Margen | P25: Nombre | Q25: Productos | R25: Cantidad | T25: Costo Prendas | W25: Precio unitario x3 | X25: Precio x3 | Y25: Margen x3 | Z25: Precio unitario x6 | AA25: Precio x6 | AB25: Margen x6 | AC25: Precio Unit x12 | AD25: Precio x12 + | AE25: Margen x12
A26: Camisa Oversize Peruana | B26: S | C26: Negro | D26: Sin estampar | E26: 1 | F26: =IF(A26="","",VLOOKUP(A26,'Cotizador Compras'!$A$5:$J$21,2,FALSE)) -> YOUR BRAND | G26: =IF(A26="","",VLOOKUP(A26,'Cotizador Compras'!$A$5:$J$21,3,FALSE)) -> 37000 | H26: =IF(OR(A26="",D26=""),"",IF(D26="Sin estampar",0,IF(D26="Pecho",VLOOKUP(A26,'Cotizador Compras'!$A$5:$J$21,4,FALSE),IF(D26="Espalda",VLOOKUP(A26,'Cotizador Compras'!$A$5:$J$21,5,FALSE),VLOOKUP(A26,'Cotizador Compras'!$A$5:$J$21,4,FALSE)+VLOOKUP(A26,'Cotizador Compras'!$A$5:$J$21,5,FALSE))))) -> 0 | I26: =IF(A26="","",VLOOKUP(A26,'Cotizador Compras'!$A$5:$J$21,6,FALSE)) -> 1700 | J26: =IF(A26="","",VLOOKUP(A26,'Cotizador Compras'!$A$5:$J$21,7,FALSE)) -> 1000 | K26: =IF(OR(A26="",E26=""),"",(G26+H26+I26+J26)*E26) -> 39700 | L26: =IF(A26="","",IF(D26="Sin estampar",VLOOKUP(A26,'Cotizador Compras'!$A$5:$J$21,8,FALSE),IF(D26="Pecho",VLOOKUP(A26,'Cotizador Compras'!$A$5:$J$21,10,FALSE),VLOOKUP(A26,'Cotizador Compras'!$A$5:$J$21,9,FALSE)))) -> 75000 | M26: =IF(OR(A26="",E26=""),"",L26*E26) -> 75000 | N26: =+G26+H26+I26+J26 -> 39700 | O26: =IF(L26>0,(L26-N26)/L26,0) -> 0.47066667 | P26: =CONCATENATE(A26," ",B26," ",C26) -> Camisa Oversize Peruana S Negro | Q26: {=+UNIQUE(P26:P163)} -> Camisa Oversize Peruana S Negro | R26: =SUMIF($P$26:$P$159,Q26,$E$26:$E$159) -> 2 | T26: =E26*G26 -> 37000 | X26: =ROUNDUP(L26*0.95,-3)*3 -> 216000 | Y26: =IF(X26>0,(X26-N26*3)/X26,0) -> 0.44861111 | AA26: =+ROUNDUP(L26*0.925,-3)*6 -> 420000 | AB26: =IF(AA26>0,(AA26-N26*6)/AA26,0) -> 0.43285714 | AC26: =+E26*AD26/12 -> 68000 | AD26: =+ROUNDUP(L26*0.9,-3)*12 -> 816000 | AE26: =IF(AD26>0,(AD26-N26*12)/AD26,0) -> 0.41617647
A27: Camisa Oversize Peruana | B27: M | C27: Negro | D27: Sin estampar | E27: 4 | F27: =IF(A27="","",VLOOKUP(A27,'Cotizador Compras'!$A$5:$J$21,2,FALSE)) -> YOUR BRAND | G27: =IF(A27="","",VLOOKUP(A27,'Cotizador Compras'!$A$5:$J$21,3,FALSE)) -> 37000 | H27: =IF(OR(A27="",D27=""),"",IF(D27="Sin estampar",0,IF(D27="Pecho",VLOOKUP(A27,'Cotizador Compras'!$A$5:$J$21,4,FALSE),IF(D27="Espalda",VLOOKUP(A27,'Cotizador Compras'!$A$5:$J$21,5,FALSE),VLOOKUP(A27,'Cotizador Compras'!$A$5:$J$21,4,FALSE)+VLOOKUP(A27,'Cotizador Compras'!$A$5:$J$21,5,FALSE))))) -> 0 | I27: =IF(A27="","",VLOOKUP(A27,'Cotizador Compras'!$A$5:$J$21,6,FALSE)) -> 1700 | J27: =IF(A27="","",VLOOKUP(A27,'Cotizador Compras'!$A$5:$J$21,7,FALSE)) -> 1000 | K27: =IF(OR(A27="",E27=""),"",(G27+H27+I27+J27)*E27) -> 158800 | L27: =IF(A27="","",IF(D27="Sin estampar",VLOOKUP(A27,'Cotizador Compras'!$A$5:$J$21,8,FALSE),IF(D27="Pecho",VLOOKUP(A27,'Cotizador Compras'!$A$5:$J$21,10,FALSE),VLOOKUP(A27,'Cotizador Compras'!$A$5:$J$21,9,FALSE)))) -> 75000 | M27: =IF(OR(A27="",E27=""),"",L27*E27) -> 300000 | N27: =+G27+H27+I27+J27 -> 39700 | O27: =IF(L27>0,(L27-N27)/L27,0) -> 0.47066667 | P27: =CONCATENATE(A27," ",B27," ",C27) -> Camisa Oversize Peruana M Negro | Q27: Camisa Oversize Peruana M Negro | R27: =SUMIF($P$26:$P$159,Q27,$E$26:$E$159) -> 6 | T27: =E27*G27 -> 148000 | X27: =ROUNDUP(L27*0.95,-3)*3 -> 216000 | Y27: =IF(X27>0,(X27-N27*3)/X27,0) -> 0.44861111 | AA27: =+ROUNDUP(L27*0.925,-3)*6 -> 420000 | AB27: =IF(AA27>0,(AA27-N27*6)/AA27,0) -> 0.43285714 | AC27: =+E27*AD27/12 -> 272000 | AD27: =+ROUNDUP(L27*0.9,-3)*12 -> 816000 | AE27: =IF(AD27>0,(AD27-N27*12)/AD27,0) -> 0.41617647
A28: Camisa Oversize Peruana | B28: L | C28: Negro | D28: Sin estampar | E28: 4 | F28: =IF(A28="","",VLOOKUP(A28,'Cotizador Compras'!$A$5:$J$21,2,FALSE)) -> YOUR BRAND | G28: =IF(A28="","",VLOOKUP(A28,'Cotizador Compras'!$A$5:$J$21,3,FALSE)) -> 37000 | H28: =IF(OR(A28="",D28=""),"",IF(D28="Sin estampar",0,IF(D28="Pecho",VLOOKUP(A28,'Cotizador Compras'!$A$5:$J$21,4,FALSE),IF(D28="Espalda",VLOOKUP(A28,'Cotizador Compras'!$A$5:$J$21,5,FALSE),VLOOKUP(A28,'Cotizador Compras'!$A$5:$J$21,4,FALSE)+VLOOKUP(A28,'Cotizador Compras'!$A$5:$J$21,5,FALSE))))) -> 0 | I28: =IF(A28="","",VLOOKUP(A28,'Cotizador Compras'!$A$5:$J$21,6,FALSE)) -> 1700 | J28: =IF(A28="","",VLOOKUP(A28,'Cotizador Compras'!$A$5:$J$21,7,FALSE)) -> 1000 | K28: =IF(OR(A28="",E28=""),"",(G28+H28+I28+J28)*E28) -> 158800 | L28: =IF(A28="","",IF(D28="Sin estampar",VLOOKUP(A28,'Cotizador Compras'!$A$5:$J$21,8,FALSE),IF(D28="Pecho",VLOOKUP(A28,'Cotizador Compras'!$A$5:$J$21,10,FALSE),VLOOKUP(A28,'Cotizador Compras'!$A$5:$J$21,9,FALSE)))) -> 75000 | M28: =IF(OR(A28="",E28=""),"",L28*E28) -> 300000 | N28: =+G28+H28+I28+J28 -> 39700 | O28: =IF(L28>0,(L28-N28)/L28,0) -> 0.47066667 | P28: =CONCATENATE(A28," ",B28," ",C28) -> Camisa Oversize Peruana L Negro | Q28: Camisa Oversize Peruana L Negro | R28: =SUMIF($P$26:$P$159,Q28,$E$26:$E$159) -> 6 | T28: =E28*G28 -> 148000 | X28: =ROUNDUP(L28*0.95,-3)*3 -> 216000 | Y28: =IF(X28>0,(X28-N28*3)/X28,0) -> 0.44861111 | AA28: =+ROUNDUP(L28*0.925,-3)*6 -> 420000 | AB28: =IF(AA28>0,(AA28-N28*6)/AA28,0) -> 0.43285714 | AC28: =+E28*AD28/12 -> 272000 | AD28: =+ROUNDUP(L28*0.9,-3)*12 -> 816000 | AE28: =IF(AD28>0,(AD28-N28*12)/AD28,0) -> 0.41617647
A29: Camisa Oversize Peruana | B29: XL | C29: Negro | D29: Sin estampar | E29: 4 | F29: =IF(A29="","",VLOOKUP(A29,'Cotizador Compras'!$A$5:$J$21,2,FALSE)) -> YOUR BRAND | G29: =IF(A29="","",VLOOKUP(A29,'Cotizador Compras'!$A$5:$J$21,3,FALSE)) -> 37000 | H29: =IF(OR(A29="",D29=""),"",IF(D29="Sin estampar",0,IF(D29="Pecho",VLOOKUP(A29,'Cotizador Compras'!$A$5:$J$21,4,FALSE),IF(D29="Espalda",VLOOKUP(A29,'Cotizador Compras'!$A$5:$J$21,5,FALSE),VLOOKUP(A29,'Cotizador Compras'!$A$5:$J$21,4,FALSE)+VLOOKUP(A29,'Cotizador Compras'!$A$5:$J$21,5,FALSE))))) -> 0 | I29: =IF(A29="","",VLOOKUP(A29,'Cotizador Compras'!$A$5:$J$21,6,FALSE)) -> 1700 | J29: =IF(A29="","",VLOOKUP(A29,'Cotizador Compras'!$A$5:$J$21,7,FALSE)) -> 1000 | K29: =IF(OR(A29="",E29=""),"",(G29+H29+I29+J29)*E29) -> 158800 | L29: =IF(A29="","",IF(D29="Sin estampar",VLOOKUP(A29,'Cotizador Compras'!$A$5:$J$21,8,FALSE),IF(D29="Pecho",VLOOKUP(A29,'Cotizador Compras'!$A$5:$J$21,10,FALSE),VLOOKUP(A29,'Cotizador Compras'!$A$5:$J$21,9,FALSE)))) -> 75000 | M29: =IF(OR(A29="",E29=""),"",L29*E29) -> 300000 | N29: =+G29+H29+I29+J29 -> 39700 | O29: =IF(L29>0,(L29-N29)/L29,0) -> 0.47066667 | P29: =CONCATENATE(A29," ",B29," ",C29) -> Camisa Oversize Peruana XL Negro | Q29: Camisa Oversize Peruana XL Negro | R29: =SUMIF($P$26:$P$159,Q29,$E$26:$E$159) -> 6 | T29: =E29*G29 -> 148000 | X29: =ROUNDUP(L29*0.95,-3)*3 -> 216000 | Y29: =IF(X29>0,(X29-N29*3)/X29,0) -> 0.44861111 | AA29: =+ROUNDUP(L29*0.925,-3)*6 -> 420000 | AB29: =IF(AA29>0,(AA29-N29*6)/AA29,0) -> 0.43285714 | AC29: =+E29*AD29/12 -> 272000 | AD29: =+ROUNDUP(L29*0.9,-3)*12 -> 816000 | AE29: =IF(AD29>0,(AD29-N29*12)/AD29,0) -> 0.41617647
A30: Camisa Oversize Peruana | B30: S | C30: Blanco | D30: Sin estampar | E30: 1 | F30: =IF(A30="","",VLOOKUP(A30,'Cotizador Compras'!$A$5:$J$21,2,FALSE)) -> YOUR BRAND | G30: =IF(A30="","",VLOOKUP(A30,'Cotizador Compras'!$A$5:$J$21,3,FALSE)) -> 37000 | H30: =IF(OR(A30="",D30=""),"",IF(D30="Sin estampar",0,IF(D30="Pecho",VLOOKUP(A30,'Cotizador Compras'!$A$5:$J$21,4,FALSE),IF(D30="Espalda",VLOOKUP(A30,'Cotizador Compras'!$A$5:$J$21,5,FALSE),VLOOKUP(A30,'Cotizador Compras'!$A$5:$J$21,4,FALSE)+VLOOKUP(A30,'Cotizador Compras'!$A$5:$J$21,5,FALSE))))) -> 0 | I30: =IF(A30="","",VLOOKUP(A30,'Cotizador Compras'!$A$5:$J$21,6,FALSE)) -> 1700 | J30: =IF(A30="","",VLOOKUP(A30,'Cotizador Compras'!$A$5:$J$21,7,FALSE)) -> 1000 | K30: =IF(OR(A30="",E30=""),"",(G30+H30+I30+J30)*E30) -> 39700 | L30: =IF(A30="","",IF(D30="Sin estampar",VLOOKUP(A30,'Cotizador Compras'!$A$5:$J$21,8,FALSE),IF(D30="Pecho",VLOOKUP(A30,'Cotizador Compras'!$A$5:$J$21,10,FALSE),VLOOKUP(A30,'Cotizador Compras'!$A$5:$J$21,9,FALSE)))) -> 75000 | M30: =IF(OR(A30="",E30=""),"",L30*E30) -> 75000 | N30: =+G30+H30+I30+J30 -> 39700 | O30: =IF(L30>0,(L30-N30)/L30,0) -> 0.47066667 | P30: =CONCATENATE(A30," ",B30," ",C30) -> Camisa Oversize Peruana S Blanco | Q30: Camisa Oversize Peruana S Blanco | R30: =SUMIF($P$26:$P$159,Q30,$E$26:$E$159) -> 2 | T30: =E30*G30 -> 37000 | X30: =ROUNDUP(L30*0.95,-3)*3 -> 216000 | Y30: =IF(X30>0,(X30-N30*3)/X30,0) -> 0.44861111 | AA30: =+ROUNDUP(L30*0.925,-3)*6 -> 420000 | AB30: =IF(AA30>0,(AA30-N30*6)/AA30,0) -> 0.43285714 | AC30: =+E30*AD30/12 -> 68000 | AD30: =+ROUNDUP(L30*0.9,-3)*12 -> 816000 | AE30: =IF(AD30>0,(AD30-N30*12)/AD30,0) -> 0.41617647
A31: Camisa Oversize Peruana | B31: M | C31: Blanco | D31: Sin estampar | E31: 4 | F31: =IF(A31="","",VLOOKUP(A31,'Cotizador Compras'!$A$5:$J$21,2,FALSE)) -> YOUR BRAND | G31: =IF(A31="","",VLOOKUP(A31,'Cotizador Compras'!$A$5:$J$21,3,FALSE)) -> 37000 | H31: =IF(OR(A31="",D31=""),"",IF(D31="Sin estampar",0,IF(D31="Pecho",VLOOKUP(A31,'Cotizador Compras'!$A$5:$J$21,4,FALSE),IF(D31="Espalda",VLOOKUP(A31,'Cotizador Compras'!$A$5:$J$21,5,FALSE),VLOOKUP(A31,'Cotizador Compras'!$A$5:$J$21,4,FALSE)+VLOOKUP(A31,'Cotizador Compras'!$A$5:$J$21,5,FALSE))))) -> 0 | I31: =IF(A31="","",VLOOKUP(A31,'Cotizador Compras'!$A$5:$J$21,6,FALSE)) -> 1700 | J31: =IF(A31="","",VLOOKUP(A31,'Cotizador Compras'!$A$5:$J$21,7,FALSE)) -> 1000 | K31: =IF(OR(A31="",E31=""),"",(G31+H31+I31+J31)*E31) -> 158800 | L31: =IF(A31="","",IF(D31="Sin estampar",VLOOKUP(A31,'Cotizador Compras'!$A$5:$J$21,8,FALSE),IF(D31="Pecho",VLOOKUP(A31,'Cotizador Compras'!$A$5:$J$21,10,FALSE),VLOOKUP(A31,'Cotizador Compras'!$A$5:$J$21,9,FALSE)))) -> 75000 | M31: =IF(OR(A31="",E31=""),"",L31*E31) -> 300000 | N31: =+G31+H31+I31+J31 -> 39700 | O31: =IF(L31>0,(L31-N31)/L31,0) -> 0.47066667 | P31: =CONCATENATE(A31," ",B31," ",C31) -> Camisa Oversize Peruana M Blanco | Q31: Camisa Oversize Peruana M Blanco | R31: =SUMIF($P$26:$P$159,Q31,$E$26:$E$159) -> 6 | T31: =E31*G31 -> 148000 | X31: =ROUNDUP(L31*0.95,-3)*3 -> 216000 | Y31: =IF(X31>0,(X31-N31*3)/X31,0) -> 0.44861111 | AA31: =+ROUNDUP(L31*0.925,-3)*6 -> 420000 | AB31: =IF(AA31>0,(AA31-N31*6)/AA31,0) -> 0.43285714 | AC31: =+E31*AD31/12 -> 272000 | AD31: =+ROUNDUP(L31*0.9,-3)*12 -> 816000 | AE31: =IF(AD31>0,(AD31-N31*12)/AD31,0) -> 0.41617647
A32: Camisa Oversize Peruana | B32: L | C32: Blanco | D32: Sin estampar | E32: 4 | F32: =IF(A32="","",VLOOKUP(A32,'Cotizador Compras'!$A$5:$J$21,2,FALSE)) -> YOUR BRAND | G32: =IF(A32="","",VLOOKUP(A32,'Cotizador Compras'!$A$5:$J$21,3,FALSE)) -> 37000 | H32: =IF(OR(A32="",D32=""),"",IF(D32="Sin estampar",0,IF(D32="Pecho",VLOOKUP(A32,'Cotizador Compras'!$A$5:$J$21,4,FALSE),IF(D32="Espalda",VLOOKUP(A32,'Cotizador Compras'!$A$5:$J$21,5,FALSE),VLOOKUP(A32,'Cotizador Compras'!$A$5:$J$21,4,FALSE)+VLOOKUP(A32,'Cotizador Compras'!$A$5:$J$21,5,FALSE))))) -> 0 | I32: =IF(A32="","",VLOOKUP(A32,'Cotizador Compras'!$A$5:$J$21,6,FALSE)) -> 1700 | J32: =IF(A32="","",VLOOKUP(A32,'Cotizador Compras'!$A$5:$J$21,7,FALSE)) -> 1000 | K32: =IF(OR(A32="",E32=""),"",(G32+H32+I32+J32)*E32) -> 158800 | L32: =IF(A32="","",IF(D32="Sin estampar",VLOOKUP(A32,'Cotizador Compras'!$A$5:$J$21,8,FALSE),IF(D32="Pecho",VLOOKUP(A32,'Cotizador Compras'!$A$5:$J$21,10,FALSE),VLOOKUP(A32,'Cotizador Compras'!$A$5:$J$21,9,FALSE)))) -> 75000 | M32: =IF(OR(A32="",E32=""),"",L32*E32) -> 300000 | N32: =+G32+H32+I32+J32 -> 39700 | O32: =IF(L32>0,(L32-N32)/L32,0) -> 0.47066667 | P32: =CONCATENATE(A32," ",B32," ",C32) -> Camisa Oversize Peruana L Blanco | Q32: Camisa Oversize Peruana L Blanco | R32: =SUMIF($P$26:$P$159,Q32,$E$26:$E$159) -> 6 | T32: =E32*G32 -> 148000 | X32: =ROUNDUP(L32*0.95,-3)*3 -> 216000 | Y32: =IF(X32>0,(X32-N32*3)/X32,0) -> 0.44861111 | AA32: =+ROUNDUP(L32*0.925,-3)*6 -> 420000 | AB32: =IF(AA32>0,(AA32-N32*6)/AA32,0) -> 0.43285714 | AC32: =+E32*AD32/12 -> 272000 | AD32: =+ROUNDUP(L32*0.9,-3)*12 -> 816000 | AE32: =IF(AD32>0,(AD32-N32*12)/AD32,0) -> 0.41617647
A33: Camisa Oversize Peruana | B33: XL | C33: Blanco | D33: Sin estampar | E33: 4 | F33: =IF(A33="","",VLOOKUP(A33,'Cotizador Compras'!$A$5:$J$21,2,FALSE)) -> YOUR BRAND | G33: =IF(A33="","",VLOOKUP(A33,'Cotizador Compras'!$A$5:$J$21,3,FALSE)) -> 37000 | H33: =IF(OR(A33="",D33=""),"",IF(D33="Sin estampar",0,IF(D33="Pecho",VLOOKUP(A33,'Cotizador Compras'!$A$5:$J$21,4,FALSE),IF(D33="Espalda",VLOOKUP(A33,'Cotizador Compras'!$A$5:$J$21,5,FALSE),VLOOKUP(A33,'Cotizador Compras'!$A$5:$J$21,4,FALSE)+VLOOKUP(A33,'Cotizador Compras'!$A$5:$J$21,5,FALSE))))) -> 0 | I33: =IF(A33="","",VLOOKUP(A33,'Cotizador Compras'!$A$5:$J$21,6,FALSE)) -> 1700 | J33: =IF(A33="","",VLOOKUP(A33,'Cotizador Compras'!$A$5:$J$21,7,FALSE)) -> 1000 | K33: =IF(OR(A33="",E33=""),"",(G33+H33+I33+J33)*E33) -> 158800 | L33: =IF(A33="","",IF(D33="Sin estampar",VLOOKUP(A33,'Cotizador Compras'!$A$5:$J$21,8,FALSE),IF(D33="Pecho",VLOOKUP(A33,'Cotizador Compras'!$A$5:$J$21,10,FALSE),VLOOKUP(A33,'Cotizador Compras'!$A$5:$J$21,9,FALSE)))) -> 75000 | M33: =IF(OR(A33="",E33=""),"",L33*E33) -> 300000 | N33: =+G33+H33+I33+J33 -> 39700 | O33: =IF(L33>0,(L33-N33)/L33,0) -> 0.47066667 | P33: =CONCATENATE(A33," ",B33," ",C33) -> Camisa Oversize Peruana XL Blanco | Q33: Camisa Oversize Peruana XL Blanco | R33: =SUMIF($P$26:$P$159,Q33,$E$26:$E$159) -> 6 | T33: =E33*G33 -> 148000 | X33: =ROUNDUP(L33*0.95,-3)*3 -> 216000 | Y33: =IF(X33>0,(X33-N33*3)/X33,0) -> 0.44861111 | AA33: =+ROUNDUP(L33*0.925,-3)*6 -> 420000 | AB33: =IF(AA33>0,(AA33-N33*6)/AA33,0) -> 0.43285714 | AC33: =+E33*AD33/12 -> 272000 | AD33: =+ROUNDUP(L33*0.9,-3)*12 -> 816000 | AE33: =IF(AD33>0,(AD33-N33*12)/AD33,0) -> 0.41617647
A34: Camisa Oversize Peruana | B34: S | C34: Perla | D34: Sin estampar | E34: 1 | F34: =IF(A34="","",VLOOKUP(A34,'Cotizador Compras'!$A$5:$J$21,2,FALSE)) -> YOUR BRAND | G34: =IF(A34="","",VLOOKUP(A34,'Cotizador Compras'!$A$5:$J$21,3,FALSE)) -> 37000 | H34: =IF(OR(A34="",D34=""),"",IF(D34="Sin estampar",0,IF(D34="Pecho",VLOOKUP(A34,'Cotizador Compras'!$A$5:$J$21,4,FALSE),IF(D34="Espalda",VLOOKUP(A34,'Cotizador Compras'!$A$5:$J$21,5,FALSE),VLOOKUP(A34,'Cotizador Compras'!$A$5:$J$21,4,FALSE)+VLOOKUP(A34,'Cotizador Compras'!$A$5:$J$21,5,FALSE))))) -> 0 | I34: =IF(A34="","",VLOOKUP(A34,'Cotizador Compras'!$A$5:$J$21,6,FALSE)) -> 1700 | J34: =IF(A34="","",VLOOKUP(A34,'Cotizador Compras'!$A$5:$J$21,7,FALSE)) -> 1000 | K34: =IF(OR(A34="",E34=""),"",(G34+H34+I34+J34)*E34) -> 39700 | L34: =IF(A34="","",IF(D34="Sin estampar",VLOOKUP(A34,'Cotizador Compras'!$A$5:$J$21,8,FALSE),IF(D34="Pecho",VLOOKUP(A34,'Cotizador Compras'!$A$5:$J$21,10,FALSE),VLOOKUP(A34,'Cotizador Compras'!$A$5:$J$21,9,FALSE)))) -> 75000 | M34: =IF(OR(A34="",E34=""),"",L34*E34) -> 75000 | N34: =+G34+H34+I34+J34 -> 39700 | O34: =IF(L34>0,(L34-N34)/L34,0) -> 0.47066667 | P34: =CONCATENATE(A34," ",B34," ",C34) -> Camisa Oversize Peruana S Perla | Q34: Camisa Oversize Peruana S Perla | R34: =SUMIF($P$26:$P$159,Q34,$E$26:$E$159) -> 2 | T34: =E34*G34 -> 37000 | X34: =ROUNDUP(L34*0.95,-3)*3 -> 216000 | Y34: =IF(X34>0,(X34-N34*3)/X34,0) -> 0.44861111 | AA34: =+ROUNDUP(L34*0.925,-3)*6 -> 420000 | AB34: =IF(AA34>0,(AA34-N34*6)/AA34,0) -> 0.43285714 | AC34: =+E34*AD34/12 -> 68000 | AD34: =+ROUNDUP(L34*0.9,-3)*12 -> 816000 | AE34: =IF(AD34>0,(AD34-N34*12)/AD34,0) -> 0.41617647
A35: Camisa Oversize Peruana | B35: M | C35: Perla | D35: Sin estampar | E35: 4 | F35: =IF(A35="","",VLOOKUP(A35,'Cotizador Compras'!$A$5:$J$21,2,FALSE)) -> YOUR BRAND | G35: =IF(A35="","",VLOOKUP(A35,'Cotizador Compras'!$A$5:$J$21,3,FALSE)) -> 37000 | H35: =IF(OR(A35="",D35=""),"",IF(D35="Sin estampar",0,IF(D35="Pecho",VLOOKUP(A35,'Cotizador Compras'!$A$5:$J$21,4,FALSE),IF(D35="Espalda",VLOOKUP(A35,'Cotizador Compras'!$A$5:$J$21,5,FALSE),VLOOKUP(A35,'Cotizador Compras'!$A$5:$J$21,4,FALSE)+VLOOKUP(A35,'Cotizador Compras'!$A$5:$J$21,5,FALSE))))) -> 0 | I35: =IF(A35="","",VLOOKUP(A35,'Cotizador Compras'!$A$5:$J$21,6,FALSE)) -> 1700 | J35: =IF(A35="","",VLOOKUP(A35,'Cotizador Compras'!$A$5:$J$21,7,FALSE)) -> 1000 | K35: =IF(OR(A35="",E35=""),"",(G35+H35+I35+J35)*E35) -> 158800 | L35: =IF(A35="","",IF(D35="Sin estampar",VLOOKUP(A35,'Cotizador Compras'!$A$5:$J$21,8,FALSE),IF(D35="Pecho",VLOOKUP(A35,'Cotizador Compras'!$A$5:$J$21,10,FALSE),VLOOKUP(A35,'Cotizador Compras'!$A$5:$J$21,9,FALSE)))) -> 75000 | M35: =IF(OR(A35="",E35=""),"",L35*E35) -> 300000 | N35: =+G35+H35+I35+J35 -> 39700 | O35: =IF(L35>0,(L35-N35)/L35,0) -> 0.47066667 | P35: =CONCATENATE(A35," ",B35," ",C35) -> Camisa Oversize Peruana M Perla | Q35: Camisa Oversize Peruana M Perla | R35: =SUMIF($P$26:$P$159,Q35,$E$26:$E$159) -> 6 | T35: =E35*G35 -> 148000 | X35: =ROUNDUP(L35*0.95,-3)*3 -> 216000 | Y35: =IF(X35>0,(X35-N35*3)/X35,0) -> 0.44861111 | AA35: =+ROUNDUP(L35*0.925,-3)*6 -> 420000 | AB35: =IF(AA35>0,(AA35-N35*6)/AA35,0) -> 0.43285714 | AC35: =+E35*AD35/12 -> 272000 | AD35: =+ROUNDUP(L35*0.9,-3)*12 -> 816000 | AE35: =IF(AD35>0,(AD35-N35*12)/AD35,0) -> 0.41617647
A36: Camisa Oversize Peruana | B36: L | C36: Perla | D36: Sin estampar | E36: 4 | F36: =IF(A36="","",VLOOKUP(A36,'Cotizador Compras'!$A$5:$J$21,2,FALSE)) -> YOUR BRAND | G36: =IF(A36="","",VLOOKUP(A36,'Cotizador Compras'!$A$5:$J$21,3,FALSE)) -> 37000 | H36: =IF(OR(A36="",D36=""),"",IF(D36="Sin estampar",0,IF(D36="Pecho",VLOOKUP(A36,'Cotizador Compras'!$A$5:$J$21,4,FALSE),IF(D36="Espalda",VLOOKUP(A36,'Cotizador Compras'!$A$5:$J$21,5,FALSE),VLOOKUP(A36,'Cotizador Compras'!$A$5:$J$21,4,FALSE)+VLOOKUP(A36,'Cotizador Compras'!$A$5:$J$21,5,FALSE))))) -> 0 | I36: =IF(A36="","",VLOOKUP(A36,'Cotizador Compras'!$A$5:$J$21,6,FALSE)) -> 1700 | J36: =IF(A36="","",VLOOKUP(A36,'Cotizador Compras'!$A$5:$J$21,7,FALSE)) -> 1000 | K36: =IF(OR(A36="",E36=""),"",(G36+H36+I36+J36)*E36) -> 158800 | L36: =IF(A36="","",IF(D36="Sin estampar",VLOOKUP(A36,'Cotizador Compras'!$A$5:$J$21,8,FALSE),IF(D36="Pecho",VLOOKUP(A36,'Cotizador Compras'!$A$5:$J$21,10,FALSE),VLOOKUP(A36,'Cotizador Compras'!$A$5:$J$21,9,FALSE)))) -> 75000 | M36: =IF(OR(A36="",E36=""),"",L36*E36) -> 300000 | N36: =+G36+H36+I36+J36 -> 39700 | O36: =IF(L36>0,(L36-N36)/L36,0) -> 0.47066667 | P36: =CONCATENATE(A36," ",B36," ",C36) -> Camisa Oversize Peruana L Perla | Q36: Camisa Oversize Peruana L Perla | R36: =SUMIF($P$26:$P$159,Q36,$E$26:$E$159) -> 6 | T36: =E36*G36 -> 148000 | X36: =ROUNDUP(L36*0.95,-3)*3 -> 216000 | Y36: =IF(X36>0,(X36-N36*3)/X36,0) -> 0.44861111 | AA36: =+ROUNDUP(L36*0.925,-3)*6 -> 420000 | AB36: =IF(AA36>0,(AA36-N36*6)/AA36,0) -> 0.43285714 | AC36: =+E36*AD36/12 -> 272000 | AD36: =+ROUNDUP(L36*0.9,-3)*12 -> 816000 | AE36: =IF(AD36>0,(AD36-N36*12)/AD36,0) -> 0.41617647
A37: Camisa Oversize Peruana | B37: XL | C37: Perla | D37: Sin estampar | E37: 4 | F37: =IF(A37="","",VLOOKUP(A37,'Cotizador Compras'!$A$5:$J$21,2,FALSE)) -> YOUR BRAND | G37: =IF(A37="","",VLOOKUP(A37,'Cotizador Compras'!$A$5:$J$21,3,FALSE)) -> 37000 | H37: =IF(OR(A37="",D37=""),"",IF(D37="Sin estampar",0,IF(D37="Pecho",VLOOKUP(A37,'Cotizador Compras'!$A$5:$J$21,4,FALSE),IF(D37="Espalda",VLOOKUP(A37,'Cotizador Compras'!$A$5:$J$21,5,FALSE),VLOOKUP(A37,'Cotizador Compras'!$A$5:$J$21,4,FALSE)+VLOOKUP(A37,'Cotizador Compras'!$A$5:$J$21,5,FALSE))))) -> 0 | I37: =IF(A37="","",VLOOKUP(A37,'Cotizador Compras'!$A$5:$J$21,6,FALSE)) -> 1700 | J37: =IF(A37="","",VLOOKUP(A37,'Cotizador Compras'!$A$5:$J$21,7,FALSE)) -> 1000 | K37: =IF(OR(A37="",E37=""),"",(G37+H37+I37+J37)*E37) -> 158800 | L37: =IF(A37="","",IF(D37="Sin estampar",VLOOKUP(A37,'Cotizador Compras'!$A$5:$J$21,8,FALSE),IF(D37="Pecho",VLOOKUP(A37,'Cotizador Compras'!$A$5:$J$21,10,FALSE),VLOOKUP(A37,'Cotizador Compras'!$A$5:$J$21,9,FALSE)))) -> 75000 | M37: =IF(OR(A37="",E37=""),"",L37*E37) -> 300000 | N37: =+G37+H37+I37+J37 -> 39700 | O37: =IF(L37>0,(L37-N37)/L37,0) -> 0.47066667 | P37: =CONCATENATE(A37," ",B37," ",C37) -> Camisa Oversize Peruana XL Perla | Q37: Camisa Oversize Peruana XL Perla | R37: =SUMIF($P$26:$P$159,Q37,$E$26:$E$159) -> 6 | T37: =E37*G37 -> 148000 | X37: =ROUNDUP(L37*0.95,-3)*3 -> 216000 | Y37: =IF(X37>0,(X37-N37*3)/X37,0) -> 0.44861111 | AA37: =+ROUNDUP(L37*0.925,-3)*6 -> 420000 | AB37: =IF(AA37>0,(AA37-N37*6)/AA37,0) -> 0.43285714 | AC37: =+E37*AD37/12 -> 272000 | AD37: =+ROUNDUP(L37*0.9,-3)*12 -> 816000 | AE37: =IF(AD37>0,(AD37-N37*12)/AD37,0) -> 0.41617647
A38: Camisa Oversize Peruana | B38: S | C38: Beige | D38: Sin estampar | E38: 1 | F38: =IF(A38="","",VLOOKUP(A38,'Cotizador Compras'!$A$5:$J$21,2,FALSE)) -> YOUR BRAND | G38: =IF(A38="","",VLOOKUP(A38,'Cotizador Compras'!$A$5:$J$21,3,FALSE)) -> 37000 | H38: =IF(OR(A38="",D38=""),"",IF(D38="Sin estampar",0,IF(D38="Pecho",VLOOKUP(A38,'Cotizador Compras'!$A$5:$J$21,4,FALSE),IF(D38="Espalda",VLOOKUP(A38,'Cotizador Compras'!$A$5:$J$21,5,FALSE),VLOOKUP(A38,'Cotizador Compras'!$A$5:$J$21,4,FALSE)+VLOOKUP(A38,'Cotizador Compras'!$A$5:$J$21,5,FALSE))))) -> 0 | I38: =IF(A38="","",VLOOKUP(A38,'Cotizador Compras'!$A$5:$J$21,6,FALSE)) -> 1700 | J38: =IF(A38="","",VLOOKUP(A38,'Cotizador Compras'!$A$5:$J$21,7,FALSE)) -> 1000 | K38: =IF(OR(A38="",E38=""),"",(G38+H38+I38+J38)*E38) -> 39700 | L38: =IF(A38="","",IF(D38="Sin estampar",VLOOKUP(A38,'Cotizador Compras'!$A$5:$J$21,8,FALSE),IF(D38="Pecho",VLOOKUP(A38,'Cotizador Compras'!$A$5:$J$21,10,FALSE),VLOOKUP(A38,'Cotizador Compras'!$A$5:$J$21,9,FALSE)))) -> 75000 | M38: =IF(OR(A38="",E38=""),"",L38*E38) -> 75000 | N38: =+G38+H38+I38+J38 -> 39700 | O38: =IF(L38>0,(L38-N38)/L38,0) -> 0.47066667 | P38: =CONCATENATE(A38," ",B38," ",C38) -> Camisa Oversize Peruana S Beige | Q38: Camisa Oversize Peruana S Beige | R38: =SUMIF($P$26:$P$159,Q38,$E$26:$E$159) -> 2 | T38: =E38*G38 -> 37000 | X38: =ROUNDUP(L38*0.95,-3)*3 -> 216000 | Y38: =IF(X38>0,(X38-N38*3)/X38,0) -> 0.44861111 | AA38: =+ROUNDUP(L38*0.925,-3)*6 -> 420000 | AB38: =IF(AA38>0,(AA38-N38*6)/AA38,0) -> 0.43285714 | AC38: =+E38*AD38/12 -> 68000 | AD38: =+ROUNDUP(L38*0.9,-3)*12 -> 816000 | AE38: =IF(AD38>0,(AD38-N38*12)/AD38,0) -> 0.41617647
... A73: Camisa Oversize Peruana | B73: XL | C73: Negro | D73: Full (Pecho+Espalda) | E73: 2 | F73: =IF(A73="","",VLOOKUP(A73,'Cotizador Compras'!$A$5:$J$21,2,FALSE)) -> YOUR BRAND | G73: =IF(A73="","",VLOOKUP(A73,'Cotizador Compras'!$A$5:$J$21,3,FALSE)) -> 37000 | H73: =IF(OR(A73="",D73=""),"",IF(D73="Sin estampar",0,IF(D73="Pecho",VLOOKUP(A73,'Cotizador Compras'!$A$5:$J$21,4,FALSE),IF(D73="Espalda",VLOOKUP(A73,'Cotizador Compras'!$A$5:$J$21,5,FALSE),VLOOKUP(A73,'Cotizador Compras'!$A$5:$J$21,4,FALSE)+VLOOKUP(A73,'Cotizador Compras'!$A$5:$J$21,5,FALSE))))) -> 14500 | I73: =IF(A73="","",VLOOKUP(A73,'Cotizador Compras'!$A$5:$J$21,6,FALSE)) -> 1700 | J73: =IF(A73="","",VLOOKUP(A73,'Cotizador Compras'!$A$5:$J$21,7,FALSE)) -> 1000 | K73: =IF(OR(A73="",E73=""),"",(G73+H73+I73+J73)*E73) -> 108400 | L73: =IF(A73="","",IF(D73="Sin estampar",VLOOKUP(A73,'Cotizador Compras'!$A$5:$J$21,8,FALSE),IF(D73="Pecho",VLOOKUP(A73,'Cotizador Compras'!$A$5:$J$21,10,FALSE),VLOOKUP(A73,'Cotizador Compras'!$A$5:$J$21,9,FALSE)))) -> 130000 | M73: =IF(OR(A73="",E73=""),"",L73*E73) -> 260000 | N73: =+G73+H73+I73+J73 -> 54200 | O73: =IF(L73>0,(L73-N73)/L73,0) -> 0.58307692 | P73: =CONCATENATE(A73," ",B73," ",C73) -> Camisa Oversize Peruana XL Negro | Q73: Buzo Cuello Redondo Oversized L Negro | R73: =SUMIF($P$26:$P$159,Q73,$E$26:$E$159) -> 4 | T73: =E73*G73 -> 74000 | X73: =ROUNDUP(L73*0.95,-3)*3 -> 372000 | Y73: =IF(X73>0,(X73-N73*3)/X73,0) -> 0.56290323 | AA73: =+ROUNDUP(L73*0.925,-3)*6 -> 726000 | AB73: =IF(AA73>0,(AA73-N73*6)/AA73,0) -> 0.55206612 | AC73: =+E73*AD73/12 -> 234000 | AD73: =+ROUNDUP(L73*0.9,-3)*12 -> 1404000 | AE73: =IF(AD73>0,(AD73-N73*12)/AD73,0) -> 0.53675214
A74: Camisa Boxy fit | B74: S | C74: Negro | D74: Sin estampar | E74: 1 | F74: YOUR BRAND | G74: =IF(A74="","",VLOOKUP(A74,'Cotizador Compras'!$A$5:$J$21,3,FALSE)) -> 37000 | H74: =IF(OR(A74="",D74=""),"",IF(D74="Sin estampar",0,IF(D74="Pecho",VLOOKUP(A74,'Cotizador Compras'!$A$5:$J$21,4,FALSE),IF(D74="Espalda",VLOOKUP(A74,'Cotizador Compras'!$A$5:$J$21,5,FALSE),VLOOKUP(A74,'Cotizador Compras'!$A$5:$J$21,4,FALSE)+VLOOKUP(A74,'Cotizador Compras'!$A$5:$J$21,5,FALSE))))) -> 0 | I74: =IF(A74="","",VLOOKUP(A74,'Cotizador Compras'!$A$5:$J$21,6,FALSE)) -> 1700 | J74: =IF(A74="","",VLOOKUP(A74,'Cotizador Compras'!$A$5:$J$21,7,FALSE)) -> 1000 | K74: =IF(OR(A74="",E74=""),"",(G74+H74+I74+J74)*E74) -> 39700 | L74: =IF(A74="","",IF(D74="Sin estampar",VLOOKUP(A74,'Cotizador Compras'!$A$5:$J$21,8,FALSE),IF(D74="Pecho",VLOOKUP(A74,'Cotizador Compras'!$A$5:$J$21,10,FALSE),VLOOKUP(A74,'Cotizador Compras'!$A$5:$J$21,9,FALSE)))) -> 75000 | M74: =IF(OR(A74="",E74=""),"",L74*E74) -> 75000 | N74: =+G74+H74+I74+J74 -> 39700 | O74: =IF(L74>0,(L74-N74)/L74,0) -> 0.47066667 | P74: =CONCATENATE(A74," ",B74," ",C74) -> Camisa Boxy fit S Negro | Q74: Buzo Cuello Redondo Oversized XL Negro | R74: =SUMIF($P$26:$P$159,Q74,$E$26:$E$159) -> 4 | T74: =E74*G74 -> 37000 | X74: =ROUNDUP(L74*0.95,-3)*3 -> 216000 | Y74: =IF(X74>0,(X74-N74*3)/X74,0) -> 0.44861111 | AA74: =+ROUNDUP(L74*0.925,-3)*6 -> 420000 | AB74: =IF(AA74>0,(AA74-N74*6)/AA74,0) -> 0.43285714 | AC74: =+E74*AD74/12 -> 68000 | AD74: =+ROUNDUP(L74*0.9,-3)*12 -> 816000 | AE74: =IF(AD74>0,(AD74-N74*12)/AD74,0) -> 0.41617647
